Workbook

Sheet Resumen
M1: Total gastos anuales | Q1: Total Ing - Egr
B2: $ | C2: u$s | F2: T/C | I2: Convertido | J2: $ | K2: u$s | N2: $ | O2: U$S | P2: Total u$s
A3: Facturacion 2023 | B3: =Facturacion!E210 -> 609549.45 | C3: =Facturacion!J210 -> 185429 | F3: T/C | G3: 39.2 | J3: =B3+C3*G3 -> 7878366.3 | K3: =C3+B3/G3 -> 200978.73 | M3: Gastos 2023 | N3: =Gastos!K1430 -> 2738459.3 | O3: =Gastos!I1430 -> 153831.82
A4: Facturacion 2024 | B4: =Facturacion!E209 -> 3576388.3 | C4: =Facturacion!J209 -> 176750.28 | F4: T/C | G4: =Facturacion!K217 -> 39.171 | J4: =B4+C4*G4 -> 10499874 | K4: =C4+B4/G4 -> 268052.22 | M4: Gastos 2024 | N4: =Gastos!K1429 -> 4991092.9 | O4: =Gastos!I1429 -> 124862.36
A5: Facturacion 2025 | B5: =Facturacion!E208 -> 2027341.1 | C5: =Facturacion!J208 -> 194567.74 | F5: T/C | G5: =Facturacion!K216 -> 41.3 | J5: =B5+C5*G5 -> 10062989 | K5: =C5+B5/G5 -> 243655.9 | M5: Gastos 2025 | N5: =Gastos!K1428 -> 5679907.3 | O5: =Gastos!I1428 -> 134679.16 | P5: =O5+N5/G5 -> 272207.18
B7: Activo | G7: Simulacion
A8: Cta.Cte. Santander m/n | B8: =CtaCteMN!G2 -> 169960.1
A9: Cta.Cte. Santander u$s | C9: =CtaCteUSS!D3 -> 9236.38 | E9: Aplicar ? | G9: $ | H9: u$s
A10: Cta.Cte. ITAU $ | B10: =CtaCteMN!R3 -> 0
A11: Cta.Cte. ITAU u$s | C11: =CtaCteUSS!L4 -> 29377.6
A12: Cta.Cte. MERCURY U$S | C12: 0 | D12: =CtaCteUSS!S4 -> -16753.33
A13: Cta.Cte. Payoneer U$S | C13: =CtaCteUSS!Z4 -> 41.96
A14: Fact. a cobrar | B14: =Facturacion!E215 -> 323713.18 | C14: =Facturacion!E216 -> 25557.7
A15: Certificados | B15: =CertificadosFinal!E50 -> 66071.501
A16: Prestamos a cobrar | B16: =G16*$E16 -> 0 | C16: =H16*$E16 -> 0 | E16: 1 | G16: =Prestamos!I4 -> 0 | H16: =Prestamos!I19 -> 0 | I16: revisar - 2/05/2025
A17: Caja Chica | B17: 0
A18: IRNR a recuperar | B18: 0
A19: Utilidades retiradas | B19: =G19*$E19 -> 0 | C19: =H19*$E19 -> 0 | D19: Control | E19: 0 | G19: 0 | H19: 65466
A20: nota: estas columnas grises se cargan manualmente para simular | D20: u$s
A21: Total activo | B21: =SUM(B8:B19) -> 559744.78 | C21: =SUM(C8:C19) -> 64213.64 | D21: =B21/G5+C21 -> 77766.782
B23: Pasivo | G23: Simulacion
A24: Cobranzas sin imputar | C24: 0 | E24: Aplicar ? | G24: $ | H24: u$s
A25: Iva a pagar m/n | B25: 0
A26: Irae a Pagar fin año | B26: 0 | C26: 15000
A27: Impuesto patrimonio | B27: =G27*$E27 -> 0 | E27: 0 | G27: 3193
A28: Prestamos a pagar | B28: 0 | C28: =Prestamos!H19 -> 13784.02
A29: Cuentas a pagar | B29: =APagar!H3 -> 0 | C29: =APagar!I3 -> 5750
A30: Licencias a pagar | B30: 0 | C30: 12564
A31: Sueldos a pagar | B31: =G31*$E31 -> 0 | C31: =H31*$E31 -> 0 | E31: 0
A32: Bps a pagar | B32: =G32*$E32 -> 0 | C32: =H32*$G32 -> 0 | E32: 0 | G32: 15223
A33: Gastos oficina a pagar | B33: =G33*$E33 -> 0 | C33: =H33*$E33 -> 0 | E33: 0 | G33: 6100 | H33: 0
A34: Utilidades socios mes | B34: =G34*$E34 -> 0 | C34: =H34*$E34 -> 0 | E34: 0 | H34: 9523.81
A35: Utilidades a pagar | B35: =G35*$E35 -> 0 | C35: =H35*$E35 -> 30374.92 | D35: Control | E35: 1 | H35: =31020.5-645.58 -> 30374.92
A36: nota: estas columnas grises se cargan manualmente para simular | D36: u$s
A37: Total pasivo | B37: =SUM(B24:B35) -> 0 | C37: =SUM(C24:C35) -> 77472.94 | D37: =B37/G5+C37 -> 77472.94
B38: $ | C38: u$s
D41: Control | G41: Utilidad total
A42: Patrimonio | B42: =B21-B37 -> 559744.78 | C42: =C21-C37 -> -13259.3 | D42: u$s | G42: Convertido u$s
B43: $ | C43: u$s | D43: =D21-D37 -> 293.84235 | G43: =(B42/G3) + C42 -> 1019.9035

Sheet FacAnual
C1: FACTURACION 2022
A3: Mes | B3: Monto s/IVA | D3: Conversion | G3: Totales | J3: Diferencia UCFE | K3: UCFE
B4: $ | C4: U$S | D4: $ | E4: t/c | F4: U$S | G4: $ | H4: U$S | J4: $ | K4: $
A5: Enero | B5: =SUM(Facturacion!G2:G6) -> 154980 | C5: =SUM(Facturacion!L2:L6) -> 33509 | D5: =SUM(Facturacion!N2:N6) -> 1486011.2 | E5: =Facturacion!M2 -> 44.475 | F5: =B5/E5 -> 3484.6543 | G5: =SUM(B5,D5) -> 1640991.2 | H5: =C5+F5 -> 36993.654 | J5: =K5-G5 -> 0.0050000001 | K5: =873177.68+767813.54 -> 1640991.2
A6: Febrero | B6: =SUM(Facturacion!G7:G12) -> 151018.2 | C6: =SUM(Facturacion!L7:L12) -> 30538 | D6: =SUM(Facturacion!N7:N12) -> 1314581 | E6: =Facturacion!M7 -> 43.074 | F6: =B6/E6 -> 3506.0176 | G6: =SUM(B6,D6) -> 1465599.2 | H6: =C6+F6 -> 34044.018 | J6: =K6-G6 -> 0 | K6: =600882.3+864716.9 -> 1465599.2
A7: Marzo | B7: =SUM(Facturacion!G13:G14) -> 0 | C7: =SUM(Facturacion!L13:L14) -> 20703 | D7: =SUM(Facturacion!N13:N14) -> 848181.21 | E7: =Facturacion!M13 -> 40.969 | F7: =B7/E7 -> 0 | G7: =SUM(B7,D7) -> 848181.21 | H7: =C7+F7 -> 20703 | J7: =K7-G7 -> 70183.173 | K7: 918364.38 | L7: diferencia tipo de cambio | N7: =J7/44.569 -> 1574.7083
A8: Abril | B8: =SUM(Facturacion!G15:G17) -> 140571.9 | C8: =SUM(Facturacion!L15:L17) -> 9824 | D8: =SUM(Facturacion!N15:N17) -> 401084.45 | E8: =Facturacion!M15 -> 40.049 | F8: =B8/E8 -> 3509.9978 | G8: =SUM(B8,D8) -> 541656.35 | H8: =C8+F8 -> 13333.998 | J8: =K8-G8 -> 0.002 | K8: =140571.9+401084.45 -> 541656.35
A9: Mayo | B9: =SUM(Facturacion!G18:G20) -> 140091.3 | C9: =SUM(Facturacion!L18:L20) -> 15416 | D9: =SUM(Facturacion!N18:N20) -> 619800.28 | E9: =Facturacion!M18 -> 39.912 | F9: =B9/E9 -> 3510.0045 | G9: =SUM(B9,D9) -> 759891.58 | H9: =C9+F9 -> 18926.005 | J9: =K9-G9 -> 0 | K9: =140091.3+619800.28 -> 759891.58
A10: Junio | B10: =SUM(Facturacion!G21:G23) -> 0 | C10: =SUM(Facturacion!L21:L23) -> 44667.5 | D10: =SUM(Facturacion!N21:N23) -> 1766018.5 | E10: =Facturacion!M21 -> 39.575 | F10: =B10/E10 -> 0 | G10: =SUM(B10,D10) -> 1766018.5 | H10: =C10+F10 -> 44667.5 | J10: =K10-G10 -> 0 | K10: =1139760+626258.49 -> 1766018.5
A11: Julio | B11: =SUM(Facturacion!G24:G28) -> 146721.6 | C11: =SUM(Facturacion!L24:L28) -> 12937.5 | D11: =SUM(Facturacion!N24:N28) -> 530541 | E11: =Facturacion!M24 -> 41.801 | F11: =B11/E11 -> 3510.0022 | G11: =SUM(B11,D11) -> 677262.6 | H11: =C11+F11 -> 16447.502 | J11: =K11-G11 -> 0 | K11: =146721.6+530541 -> 677262.6
A12: Agosto | B12: =SUM(Facturacion!G29:G31) -> 143120.7 | C12: =SUM(Facturacion!L29:L31) -> 15387.18 | D12: =SUM(Facturacion!N29:N31) -> 627104.52 | E12: =Facturacion!M29 -> 40.755 | F12: =B12/E12 -> 3511.7335 | G12: =SUM(B12,D12) -> 770225.22 | H12: =C12+F12 -> 18898.914 | J12: =K12-G12 -> -0.0009000001 | K12: =770225.22 -> 770225.22
A13: Setiembre | B13: =SUM(Facturacion!G32:G35) -> 0 | C13: =SUM(Facturacion!L32:L35) -> 24137 | D13: =SUM(Facturacion!N32:N35) -> 1003857.8 | E13: =Facturacion!M32 -> 41.59 | F13: =B13/E13 -> 0 | G13: =SUM(B13,D13) -> 1003857.8 | H13: =C13+F13 -> 24137 | J13: =K13-G13 -> 0 | K13: =691932.83+311925 -> 1003857.8 | L13: Factura de exportacion
A14: Octubre | B14: =SUM(Facturacion!G36:G39) -> 0 | C14: =SUM(Facturacion!L36:L39) -> 23282.5 | D14: =SUM(Facturacion!N36:N39) -> 947768.54 | E14: =Facturacion!M36 -> 41.24 | F14: =B14/E14 -> 0 | G14: =SUM(B14,D14) -> 947768.54 | H14: =C14+F14 -> 23282.5 | J14: =K14-G14 -> 8145.8175 | K14: =197952+445594.04+304267.5+8100.82 -> 955914.36 | L14: Factura de exportacion
A15: Noviembre | B15: =SUM(Facturacion!G40:G43) -> 0 | C15: =SUM(Facturacion!L40:L43) -> 24318.5 | D15: =SUM(Facturacion!N40:N43) -> 959663.81 | E15: =Facturacion!M40 -> 39.801 | F15: =B15/E15 -> 0 | G15: =SUM(B15,D15) -> 959663.81 | H15: =C15+F15 -> 24318.5 | J15: =K15-G15 -> -0.0014999999 | K15: =191044.8+473276.51+295342.5 -> 959663.81 | L15: Factura de exportacion
A16: Diciembre | B16: =SUM(Facturacion!G44:G50) -> 274428 | C16: =SUM(Facturacion!L44:L50) -> 37682.82 | D16: =SUM(Facturacion!N44:N50) -> 1504117.9 | E16: =Facturacion!M44 -> 38.848 | F16: =B16/E16 -> 7064.1474 | G16: =SUM(B16,D16) -> 1778545.9 | H16: =C16+F16 -> 44746.967 | J16: =K16-G16 -> 53.99978 | K16: =186470.4+274482+1017114.98+300532.5 -> 1778599.9 | L16: Factura de exportacion
G19: Promedio | H19: =ROUND(SUM(H5:H17)/COUNT(H5:H17),2) -> 26708.3
B20: $ | C20: u$s | J20: =K20-B25 -> 78382.995 | K20: =SUM(K5:K17) -> 13238045
A21: Total facturado 2022 | B21: =SUM(B5:B17) -> 1150931.7 | C21: =SUM(C5:C17) -> 292403
A23: Total facturado expresado en
B24: $ | C24: u$s
B25: =SUM(G5:G17) -> 13159662 | C25: =SUM(H5:H17) -> 320499.56
C28: FACTURACION 2023
A30: Mes | B30: Monto s/IVA | D30: Conversion | G30: Totales | J30: Diferencia UCFE | K30: UCFE
B31: $ | C31: U$S | D31: $ | E31: t/c | F31: U$S | G31: $ | H31: U$S | J31: $ | K31: $ - fac con IVA | L31: $ - factura de exportacion
A32: Enero | B32: =SUM(Facturacion!G51:G53) -> 0 | C32: =SUM(Facturacion!L51:L53) -> 16800 | D32: =SUM(Facturacion!N51:N53) -> 653368.8 | E32: =Facturacion!M51 -> 39.241 | F32: =B32/E32 -> 0 | G32: =SUM(B32,D32) -> 653368.8 | H32: =C32+F32 -> 16800 | J32: =(K32+L32)-G32 -> 0 | K32: =188356.8+174379.5 -> 362736.3 | L32: =290632.5 -> 290632.5
A33: Febrero | B33: =SUM(Facturacion!G54:G56) -> 0 | C33: =SUM(Facturacion!L54:L56) -> 7781.44 | D33: =SUM(Facturacion!N54:N56) -> 302453.67 | E33: =Facturacion!M54 -> 38.764 | F33: =B33/E33 -> 0 | G33: =SUM(B33,D33) -> 302453.67 | H33: =C33+F33 -> 7781.44 | J33: =(K33+L33)-G33 -> -0.0032799999 | K33: =186067.2+46844.4 -> 232911.6 | L33: 69542.07
A34: Marzo | B34: =SUM(Facturacion!G57:G59) -> 0 | C34: =SUM(Facturacion!L57:L59) -> 15850 | D34: =SUM(Facturacion!N57:N59) -> 616062.75 | E34: =Facturacion!M57 -> 38.945 | F34: =B34/E34 -> 0 | G34: =SUM(B34,D34) -> 616062.75 | H34: =C34+F34 -> 15850 | J34: =(K34+L34)-G34 -> 0 | K34: =186936+137864.25 -> 324800.25 | L34: 291262.5
A35: Abril | B35: =SUM(Facturacion!G60:G62) -> 0 | C35: =SUM(Facturacion!L60:L62) -> 15875 | D35: =SUM(Facturacion!N60:N62) -> 616568.12 | E35: =Facturacion!M60 -> 38.968 | F35: =B35/E35 -> 0 | G35: =SUM(B35,D35) -> 616568.12 | H35: =C35+F35 -> 15875 | J35: =(K35+L35)-G35 -> -0.005 | K35: =187046.4+138649.22 -> 325695.62 | L35: =290872.5 -> 290872.5
A36: Mayo | B36: =SUM(Facturacion!G63:G64) -> 0 | C36: =SUM(Facturacion!L63:L64) -> 9844 | D36: =SUM(Facturacion!N63:N64) -> 381346.72 | E36: =Facturacion!M63 -> 38.739 | F36: =B36/E36 -> 0 | G36: =SUM(B36,D36) -> 381346.72 | H36: =C36+F36 -> 9844 | J36: =(K36+L36)-G36 -> 15.494 | K36: 145271.25 | L36: 236090.96
A37: Junio | B37: 0 | C37: 0 | D37: 0 | E37: 0 | F37: 0 | G37: 0 | H37: 0 | J37: =(K37+L37)-G37 -> 0
A38: Julio | B38: =SUM(Facturacion!G65:G68) -> 0 | C38: =SUM(Facturacion!L65:L68) -> 21894.48 | D38: =SUM(Facturacion!N65:N68) -> 822753.64 | E38: =Facturacion!M65 -> 37.493 | F38: =B38/E38 -> 0 | G38: =SUM(B38,D38) -> 822753.64 | H38: =C38+F38 -> 21894.48 | J38: =(K38+L38)-G38 -> 0.00136 | K38: =155595.95+128057.6 -> 283653.55 | L38: =282480+256620.09 -> 539100.09
A39: Agosto | B39: =SUM(Facturacion!G69:G70) -> 0 | C39: =SUM(Facturacion!L69:L70) -> 11550 | D39: =SUM(Facturacion!N69:N70) -> 435227.1 | E39: =Facturacion!M69 -> 37.682 | F39: =B39/E39 -> 0 | G39: =SUM(B39,D39) -> 435227.1 | H39: =C39+F39 -> 11550 | J39: =(K39+L39)-G39 -> 0 | K39: =152612.1 -> 152612.1 | L39: 282615
A40: Setiembre | B40: =SUM(Facturacion!G71:G73) -> 0 | C40: =SUM(Facturacion!L71:L73) -> 24434.08 | D40: =SUM(Facturacion!N71:N73) -> 939478.79 | E40: =Facturacion!M71 -> 38.285 | F40: =B40/E40 -> 0 | G40: =SUM(B40,D40) -> 939478.79 | H40: =C40+F40 -> 24434.08 | J40: =(K40+L40)-G40 -> 0.0015200002 | K40: =367536+160007.4 -> 527543.4 | L40: 411935.39
A41: Octubre | B41: =SUM(Facturacion!G74:G75) -> 0 | C41: =SUM(Facturacion!L74:L75) -> 17900 | D41: =SUM(Facturacion!N74:N75) -> 715140.8 | E41: =Facturacion!M74 -> 39.952 | F41: =B41/E41 -> 0 | G41: =SUM(B41,D41) -> 715140.8 | H41: =C41+F41 -> 17900 | J41: =(K41+L41)-G41 -> 0 | K41: 175788.8 | L41: 539352
A42: Noviembre | B42: =SUM(Facturacion!G76:G78) -> 368334.64 | C42: =SUM(Facturacion!L76:L78) -> 17600 | D42: =SUM(Facturacion!N76:N78) -> 688001.6 | E42: =Facturacion!M78 -> 39.091 | F42: =B42/E42 -> 9422.4921 | G42: =SUM(B42,D42) -> 1056336.2 | H42: =C42+F42 -> 27022.492 | J42: =(K42+L42)-G42 -> 0 | K42: =528607.74 -> 528607.74 | L42: 527728.5
A43: Diciembre | B43: =SUM(Facturacion!G79:G82) -> 241214.81 | C43: =SUM(Facturacion!L79:L82) -> 25900 | D43: =SUM(Facturacion!N79:N82) -> 1013415.4 | E43: =Facturacion!M79 -> 39.308 | F43: =B43/E43 -> 6136.5323 | G43: =SUM(B43,D43) -> 1254630.2 | H43: =C43+F43 -> 32036.532 | J43: =(K43+L43)-G43 -> 0 | K43: =377356.8+391449.51 -> 768806.31 | L43: 485823.9
G46: Promedio | H46: =ROUND(SUM(H32:H44)/COUNT(H32:H44),2) -> 16749
B47: $ | C47: u$s | J47: =K47-B52 -> -3964939.9 | K47: =SUM(K32:K44) -> 3828426.9 | L47: =SUM(L32:L44) -> 3964955.4
A48: Total facturado 2023 | B48: =SUM(B32:B44) -> 609549.45 | C48: =SUM(C32:C44) -> 185429
A50: Total facturado expresado en
...

Sheet Facturacion
B1: Factura | C1: Cliente | D1: Mes | E1: C.Costos | F1: Tema | G1: Neto m/n | H1: Cobrado? | I1: Iva | J1: Pagado? | K1: Monto m/n | L1: Neto u$s | M1: t/c | N1: Convertido $ | O1: Monto u$s | P1: Exonerado | Q1: A cobrar $ | R1: A cobrar u$s | S1: A cuenta $ | T1: A cuenta $s
A2: A001 | B2: A001 | C2: UXDivers | D2: 26/01/2022 | F2: web orders/Team Minder web | H2: S | I2: =N2*0.22 -> 41094.9 | J2: S | L2: 4200 | M2: 44.475 | N2: =L2*M2 -> 186795 | O2: =L2*1.22 -> 5124 | P2: S | Q2: =IF(AND(H2<>"S", K2-S2 > 0),K2, 0) -> 0 | R2: =IF(AND(H2<>"S", L2 > 0),O2-T2, 0) -> 0 | T2: 4200
A3: A002 | B3: A002 | C3: UXDivers | D3: 26/01/2022 | H3: S | I3: =N3*0.22 -> 151004.19 | J3: S | L3: 15433 | M3: 44.475 | N3: =L3*M3 -> 686382.68 | O3: =L3*1.22 -> 18828.26 | P3: S | Q3: =IF(AND(H3<>"S", K3-S3 > 0),K3, 0) -> 0 | R3: =IF(AND(H3<>"S", L3 > 0),O3-T3, 0) -> 0 | T3: 15433
A4: A003 | B4: A003 | C4: Mevir | D4: 31/01/2022 | G4: 154980 | H4: S | I4: =G4*0.22 -> 34095.6 | J4: S | K4: =G4*1.22 -> 189075.6 | M4: 44.165 | N4: =L4*M4 -> 0 | O4: =L4*1.22 -> 0 | P4: S | Q4: =IF(AND(H4<>"S", K4-S4 > 0),K4, 0) -> 0 | R4: =IF(AND(H4<>"S", L4 > 0),O4-T4, 0) -> 0
A5: A004 | B5: A004 | C5: UXDivers | D5: 31/01/2022 | H5: S | I5: =N5*0.22 -> 31577.975 | J5: S | L5: 3250 | M5: 44.165 | N5: =L5*M5 -> 143536.25 | O5: =L5*1.22 -> 3965 | P5: S | Q5: =IF(AND(H5<>"S", K5-S5 > 0),K5, 0) -> 0 | R5: =IF(AND(H5<>"S", L5 > 0),O5-T5, 0) -> 0 | T5: 3250
A6: A005 | B6: A005 | C6: UXDivers | D6: 31/01/2022 | H6: S | I6: =N6*0.22 -> 103245.4 | J6: S | L6: 10626 | M6: 44.165 | N6: =L6*M6 -> 469297.29 | O6: =L6*1.22 -> 12963.72 | P6: S | Q6: =IF(AND(H6<>"S", K6-S6 > 0),K6, 0) -> 0 | R6: =IF(AND(H6<>"S", L6 > 0),O6-T6, 0) -> 0 | T6: 10626
A7: A006 | B7: A006 | C7: Ingesol | D7: 16/02/2022 | I7: =N7*0.22 -> 183366.02 | J7: S | L7: 19350 | M7: 43.074 | N7: =L7*M7 -> 833481.9 | O7: =L7*1.22 -> 23607 | P7: S | Q7: =IF(AND(H7<>"S", K7-S7 > 0),K7, 0) -> 0 | R7: =IF(AND(H7<>"S", L7 > 0),O7-T7, 0) -> 23607
A8: A001 | B8: A001 | C8: Ingesol | D8: 16/02/2022 | I8: =N8*0.22 -> -183366.02 | L8: -19350 | M8: 43.074 | N8: =L8*M8 -> -833481.9 | O8: =L8*1.22 -> -23607 | P8: S | Q8: =IF(AND(H8<>"S", K8-S8 > 0),K8, 0) -> 0 | R8: =IF(AND(H8<>"S", L8 > 0),O8-T8, 0) -> 0
A9: A007 | B9: A007 | C9: Ingesol | D9: 16/02/2022 | H9: S | I9: =N9*0.22 -> 132194.11 | J9: S | L9: 13950 | M9: 43.074 | N9: =L9*M9 -> 600882.3 | O9: =L9*1.22 -> 17019 | P9: S | Q9: =IF(AND(H9<>"S", K9-S9 > 0),K9, 0) -> 0 | R9: =IF(AND(H9<>"S", L9 > 0),O9-T9, 0) -> 0
A10: A008 | B10: A008 | C10: Mevir | D10: 25/02/2022 | G10: 151018.2 | H10: S | I10: =G10*0.22 -> 33224.004 | J10: S | K10: =G10*1.22 -> 184242.2 | M10: 43.025 | N10: =L10*M10 -> 0 | O10: =L10*1.22 -> 0 | P10: S | Q10: =IF(AND(H10<>"S", K10-S10 > 0),K10, 0) -> 0 | R10: =IF(AND(H10<>"S", L10 > 0),O10-T10, 0) -> 0
A11: A009 | B11: A009 | C11: UXDivers | D11: 25/02/2022 | H11: S | I11: =N11*0.22 -> 35968.9 | J11: S | L11: 3800 | M11: 43.025 | N11: =L11*M11 -> 163495 | O11: =L11*1.22 -> 4636 | P11: S | Q11: =IF(AND(H11<>"S", K11-S11 > 0),K11, 0) -> 0 | R11: =IF(AND(H11<>"S", L11 > 0),O11-T11, 0) -> 0 | T11: 3800
A12: A010 | B12: A010 | C12: UXDivers | D12: 25/02/2022 | H12: S | I12: =N12*0.22 -> 121044.81 | J12: S | L12: 12788 | M12: 43.025 | N12: =L12*M12 -> 550203.7 | O12: =L12*1.22 -> 15601.36 | P12: S | Q12: =IF(AND(H12<>"S", K12-S12 > 0),K12, 0) -> 0 | R12: =IF(AND(H12<>"S", L12 > 0),O12-T12, 0) -> 0 | T12: =7788+5000 -> 12788
A13: A011 | B13: A011 | C13: UXDivers | D13: 31/03/2022 | F13: web orders | H13: S | I13: =N13*0.22 -> 39207.333 | J13: S | L13: 4350 | M13: 40.969 | N13: =L13*M13 -> 178215.15 | O13: =L13*1.22 -> 5307 | P13: S | Q13: =IF(AND(H13<>"S", K13-S13 > 0),K13, 0) -> 0 | R13: =IF(AND(H13<>"S", L13 > 0),O13-T13, 0) -> 0 | T13: 4350
A14: A012 | B14: A012 | C14: UXDivers | D14: 31/03/2022 | F14: greatvines | H14: S | I14: =N14*0.22 -> 147392.53 | J14: S | L14: 16353 | M14: 40.969 | N14: =L14*M14 -> 669966.06 | O14: =L14*1.22 -> 19950.66 | P14: S | Q14: =IF(AND(H14<>"S", K14-S14 > 0),K14, 0) -> 0 | R14: =IF(AND(H14<>"S", L14 > 0),O14-T14, 0) -> 0 | T14: 16353
A15: A013 | B15: A013 | C15: Mevir | D15: 25/04/2022 | F15: Manejo de archivos | Gestión Mevir | SIM | G15: 140571.9 | H15: S | I15: =G15*0.22 -> 30925.818 | J15: S | K15: =G15*1.22 -> 171497.72 | M15: 40.049 | N15: =L15*M15 -> 0 | O15: =L15*1.22 -> 0 | P15: S | Q15: =IF(AND(H15<>"S", K15-S15 > 0),K15, 0) -> 0 | R15: =IF(AND(H15<>"S", L15 > 0),O15-T15, 0) -> 0
A16: A014 | B16: A014 | C16: UXDivers | D16: 30/04/2022 | F16: web orders | H16: S | I16: =N16*0.22 -> 28742.208 | J16: S | L16: 3200 | M16: 40.827 | N16: =L16*M16 -> 130646.4 | O16: =L16*1.22 -> 3904 | P16: S | Q16: =IF(AND(H16<>"S", K16-S16 > 0),K16, 0) -> 0 | R16: =IF(AND(H16<>"S", L16 > 0),O16-T16, 0) -> 0 | T16: 3200
A17: A015 | B17: A015 | C17: UXDivers | D17: 30/04/2022 | F17: Greatvines | H17: S | I17: =N17*0.22 -> 59496.371 | J17: S | L17: 6624 | M17: 40.827 | N17: =L17*M17 -> 270438.05 | O17: =L17*1.22 -> 8081.28 | P17: S | Q17: =IF(AND(H17<>"S", K17-S17 > 0),K17, 0) -> 0 | R17: =IF(AND(H17<>"S", L17 > 0),O17-T17, 0) -> 0 | T17: 6624
A18: A016 | B18: A016 | C18: Mevir | D18: 25/05/2022 | G18: 140091.3 | H18: S | I18: =G18*0.22 -> 30820.086 | J18: S | K18: =G18*1.22 -> 170911.39 | M18: 39.912 | N18: =L18*M18 -> 0 | O18: =L18*1.22 -> 0 | P18: S | Q18: =IF(AND(H18<>"S", K18-S18 > 0),K18, 0) -> 0 | R18: =IF(AND(H18<>"S", L18 > 0),O18-T18, 0) -> 0
A19: A017 | B19: A017 | C19: UXDivers | D19: 31/05/2022 | F19: web orders | H19: S | I19: =N19*0.22 -> 38807.876 | J19: S | L19: 4387.5 | M19: 40.205 | N19: =L19*M19 -> 176399.44 | O19: =L19*1.22 -> 5352.75 | P19: S | Q19: =IF(AND(H19<>"S", K19-S19 > 0),K19, 0) -> 0 | R19: =IF(AND(H19<>"S", L19 > 0),O19-T19, 0) -> 0 | T19: 4387.5
A20: A018 | B20: A018 | C20: UXDivers | D20: 31/05/2022 | F20: Greatvines | H20: S | I20: =N20*0.22 -> 97548.185 | J20: S | L20: 11028.5 | M20: 40.205 | N20: =L20*M20 -> 443400.84 | O20: =L20*1.22 -> 13454.77 | P20: S | Q20: =IF(AND(H20<>"S", K20-S20 > 0),K20, 0) -> 0 | R20: =IF(AND(H20<>"S", L20 > 0),O20-T20, 0) -> 0 | T20: 11028.5
A21: A019 | B21: A019 | C21: Ingesol | D21: 13/06/2022 | E21: Sets | F21: Anticipo inicial 30% - SETS | H21: S | I21: =N21*0.22 -> 250747.2 | J21: S | L21: 28800 | M21: 39.575 | N21: =L21*M21 -> 1139760 | O21: =L21*1.22 -> 35136 | P21: S | Q21: =IF(AND(H21<>"S", K21-S21 > 0),K21, 0) -> 0 | R21: =IF(AND(H21<>"S", L21 > 0),O21-T21, 0) -> 0
A22: A020 | B22: A020 | C22: UXDivers | D22: 30/06/2022 | F22: web orders | H22: S | I22: =N22*0.22 -> 35925.747 | J22: S | L22: 4137.5 | M22: 39.468 | N22: =L22*M22 -> 163298.85 | O22: =L22*1.22 -> 5047.75 | P22: S | Q22: =IF(AND(H22<>"S", K22-S22 > 0),K22, 0) -> 0 | R22: =IF(AND(H22<>"S", L22 > 0),O22-T22, 0) -> 0 | T22: 4137.5
A23: A021 | B23: A021 | C23: UXDivers | D23: 30/06/2022 | F23: Greatvines | H23: S | I23: =N23*0.22 -> 101851.12 | J23: S | L23: 11730 | M23: 39.468 | N23: =L23*M23 -> 462959.64 | O23: =L23*1.22 -> 14310.6 | P23: S | Q23: =IF(AND(H23<>"S", K23-S23 > 0),K23, 0) -> 0 | R23: =IF(AND(H23<>"S", L23 > 0),O23-T23, 0) -> 0 | T23: 11730
A24: A022 | B24: A022 | C24: Mevir | D24: 25/07/2022 | I24: =N24*0.22 -> 1349284.1 | J24: S | L24: 146721.6 | M24: 41.801 | N24: =L24*M24 -> 6133109.6 | O24: =L24*1.22 -> 179000.35 | P24: S | Q24: =IF(AND(H24<>"S", K24-S24 > 0),K24, 0) -> 0
A25: A002 | B25: A002 | C25: Mevir | D25: 25/07/2022 | I25: =N25*0.22 -> -1349284.1 | L25: -146721.6 | M25: 41.801 | N25: =L25*M25 -> -6133109.6 | O25: =L25*1.22 -> -179000.35 | P25: S | Q25: =IF(AND(H25<>"S", K25-S25 > 0),K25, 0) -> 0 | R25: =IF(AND(H25<>"S", L25 > 0),O25-T25, 0) -> 0
A26: A023 | B26: A023 | C26: Mevir | D26: 25/07/2022 | G26: 146721.6 | H26: S | I26: =G26*0.22 -> 32278.752 | J26: S | K26: =G26*1.22 -> 179000.35 | M26: 41.801 | N26: =L26*M26 -> 0 | O26: =L26*1.22 -> 0 | P26: S | Q26: =IF(AND(H26<>"S", K26-S26 > 0),K26, 0) -> 0 | R26: =IF(AND(H26<>"S", L26 > 0),O26-T26, 0) -> 0
A27: A024 | B27: A024 | C27: UXDivers | D27: 29/07/2022 | F27: GreatVines | H27: S | I27: =N27*0.22 -> 83000.192 | J27: S | L27: 9200 | M27: 41.008 | N27: =L27*M27 -> 377273.6 | O27: =L27*1.22 -> 11224 | P27: S | Q27: =IF(AND(H27<>"S", K27-S27 > 0),K27, 0) -> 0 | R27: =IF(AND(H27<>"S", L27 > 0),O27-T27, 0) -> 0 | T27: 9200
A28: A025 | B28: A025 | C28: UXDivers | D28: 29/07/2022 | F28: web orders | H28: S | I28: =N28*0.22 -> 33718.828 | J28: S | L28: 3737.5 | M28: 41.008 | N28: =L28*M28 -> 153267.4 | O28: =L28*1.22 -> 4559.75 | P28: S | Q28: =IF(AND(H28<>"S", K28-S28 > 0),K28, 0) -> 0 | R28: =IF(AND(H28<>"S", L28 > 0),O28-T28, 0) -> 0 | T28: 3737.5
A29: A026 | B29: A026 | C29: Mevir | D29: 31/08/2022 | G29: 143120.7 | H29: S | I29: =G29*0.22 -> 31486.554 | J29: S | K29: =G29*1.22 -> 174607.25 | M29: 40.755 | N29: =L29*M29 -> 0 | O29: =L29*1.22 -> 0 | P29: S | Q29: =IF(AND(H29<>"S", K29-S29 > 0),K29, 0) -> 0 | R29: =IF(AND(H29<>"S", L29 > 0),O29-T29, 0) -> 0
A30: A027 | B30: A027 | C30: UXDivers | D30: 31/08/2022 | F30: web orders | H30: S | I30: =N30*0.22 -> 37397.603 | J30: S | L30: 4171 | M30: 40.755 | N30: =L30*M30 -> 169989.11 | O30: =L30*1.22 -> 5088.62 | P30: S | Q30: =IF(AND(H30<>"S", K30-S30 > 0),K30, 0) -> 0 | R30: =IF(AND(H30<>"S", L30 > 0),O30-T30, 0) -> 0 | T30: 4171
A31: A028 | B31: A028 | C31: UXDivers | D31: 31/08/2022 | F31: GreatVines | H31: S | I31: =N31*0.22 -> 100565.39 | J31: S | L31: 11216.18 | M31: 40.755 | N31: =L31*M31 -> 457115.42 | O31: =L31*1.22 -> 13683.74 | P31: S | Q31: =IF(AND(H31<>"S", K31-S31 > 0),K31, 0) -> 0 | R31: =IF(AND(H31<>"S", L31 > 0),O31-T31, 0) -> 0 | T31: 11216.18
A32: A029 | B32: A029 | C32: Ingesol | D32: 30/09/2022 | E32: Sets | F32: Iteración 1 de 8 | H32: S | I32: =N32*0.22 -> 43919.04 | J32: S | L32: 4800 | M32: 41.59 | N32: =L32*M32 -> 199632 | O32: =L32*1.22 -> 5856 | P32: S | Q32: =IF(AND(H32<>"S", K32-S32 > 0),K32, 0) -> 0 | R32: =IF(AND(H32<>"S", L32 > 0),O32-T32, 0) -> 0
A33: A030 | B33: A030 | C33: UXDivers | D33: 30/09/2022 | F33: web orders | H33: S | I33: =N33*0.22 -> 35912.965 | J33: S | L33: 3925 | M33: 41.59 | N33: =L33*M33 -> 163240.75 | O33: =L33*1.22 -> 4788.5 | P33: S | Q33: =IF(AND(H33<>"S", K33-S33 > 0),K33, 0) -> 0 | R33: =IF(AND(H33<>"S", L33 > 0),O33-T33, 0) -> 0 | T33: 3925
A34: A031 | B34: A031 | C34: UXDivers | D34: 30/09/2022 | F34: GreatVines | H34: S | I34: =N34*0.22 -> 72393.218 | J34: S | L34: 7912 | M34: 41.59 | N34: =L34*M34 -> 329060.08 | O34: =L34*1.22 -> 9652.64 | P34: S | Q34: =IF(AND(H34<>"S", K34-S34 > 0),K34, 0) -> 0 | R34: =IF(AND(H34<>"S", L34 > 0),O34-T34, 0) -> 0 | T34: 7912
A35: A01 | B35: A01 | C35: OrgaPlus | D35: 30/09/2022 | F35: E-Factura de Exportacion | H35: S | I35: 0 | L35: 7500 | M35: 41.59 | N35: =L35*M35 -> 311925 | O35: =L35 -> 7500 | P35: S | Q35: =IF(AND(H35<>"S", K35-S35 > 0),K35, 0) -> 0 | R35: =IF(AND(H35<>"S", L35 > 0),O35-T35, 0) -> 0
A36: A032 | B36: A032 | C36: Ingesol | D36: 20/10/2022 | E36: Sets | F36: Iteracion 2 de 8 | H36: S | I36: =N36*0.22 -> 43549.44 | J36: S | L36: 4800 | M36: 41.24 | N36: =L36*M36 -> 197952 | O36: =L36*1.22 -> 5856 | P36: S | Q36: =IF(AND(H36<>"S", K36-S36 > 0),K36, 0) -> 0 | R36: =IF(AND(H36<>"S", L36 > 0),O36-T36, 0) -> 0
A37: A033 | B37: A033 | C37: UXDivers | D37: 31/10/2022 | F37: web orders | H37: S | I37: =N37*0.22 -> 30791.871 | J37: S | L37: 3450 | M37: 40.569 | N37: =L37*M37 -> 139963.05 | O37: =L37*1.22 -> 4209 | P37: S | Q37: =IF(AND(H37<>"S", K37-S37 > 0),K37, 0) -> 0 | R37: =IF(AND(H37<>"S", L37 > 0),O37-T37, 0) -> 0 | T37: 3450
A38: A034 | B38: A034 | C38: UXDivers | D38: 31/10/2022 | F38: GreatVines | H38: S | I38: =N38*0.22 -> 67228.918 | J38: S | L38: 7532.5 | M38: 40.569 | N38: =L38*M38 -> 305585.99 | O38: =L38*1.22 -> 9189.65 | P38: S | Q38: =IF(AND(H38<>"S", K38-S38 > 0),K38, 0) -> 0 | R38: =IF(AND(H38<>"S", L38 > 0),O38-T38, 0) -> 0 | T38: 7532.5
A39: A02 | B39: A02 | C39: OrgaPlus | D39: 31/10/2022 | F39: E-Factura de Exportacion | H39: S | L39: 7500 | M39: 40.569 | N39: =L39*M39 -> 304267.5 | O39: =L39 -> 7500 | P39: S | Q39: =IF(AND(H39<>"S", K39-S39 > 0),K39, 0) -> 0 | R39: =IF(AND(H39<>"S", L39 > 0),O39-T39, 0) -> 0
A40: A035 | B40: A035 | C40: Ingesol | D40: 20/11/2022 | E40: Sets | F40: Iteracion 3 de 8 | H40: S | I40: =N40*0.22 -> 42029.856 | J40: S | L40: 4800 | M40: 39.801 | N40: =L40*M40 -> 191044.8 | O40: =L40*1.22 -> 5856 | P40: S | Q40: =IF(AND(H40<>"S", K40-S40 > 0),K40, 0) -> 0 | R40: =IF(AND(H40<>"S", L40 > 0),O40-T40, 0) -> 0
...

Sheet Irae
A2: Imponible $ 2022 | B2: Facturacion $ | C2: Anticipos Irae | D2: $ | F2: IRAE S/deduc | G2: IRAE C/d u$s | H2: T/C | I2: Aporte patronal
A3: =Facturacion!J219-Facturacion!O219 -> 0 | B3: =FacAnual!G5 -> 1640991.2 | C3: Enero | D3: 6180 | F3: 6180 | G3: =F3/H3 -> 140.45455 | H3: 44 | I3: 0
B4: =FacAnual!G6 -> 1465599.2 | C4: Febrebro | D4: 6180 | F4: 6180 | G4: =F4/H4 -> #REF! | H4: =#REF! -> #REF! | I4: 0
B5: =FacAnual!G7 -> 848181.21 | C5: Marzo | D5: 6180 | F5: 6180 | G5: =F5/H5 -> #REF! | H5: =#REF! -> #REF! | I5: 0
B6: =FacAnual!G8 -> 541656.35 | C6: Abril | D6: 0 | F6: 0 | G6: =F6/H6 -> #REF! | H6: =#REF! -> #REF! | I6: 0
B7: =FacAnual!G9 -> 759891.58 | C7: Mayo | D7: 0 | F7: 0 | G7: =F7/H7 -> #REF! | H7: =#REF! -> #REF! | I7: 0
B8: =FacAnual!G10 -> 1766018.5 | C8: Junio | D8: 0 | F8: 0 | G8: =F8/H8 -> #REF! | H8: =#REF! -> #REF! | I8: 0
B9: =FacAnual!G11 -> 677262.6 | C9: Julio | D9: 0 | F9: 0 | G9: =F9/H9 -> #REF! | H9: =#REF! -> #REF! | I9: 0
A10: coef irae | B10: =FacAnual!G12 -> 770225.22 | C10: Agosto | D10: 0 | F10: 0 | G10: =F10/H10 -> #REF! | H10: =#REF! -> #REF! | I10: 0
A11: 0.12 | B11: =FacAnual!G13 -> 1003857.8 | C11: Setiembre | D11: 0 | F11: 0 | G11: =F11/H11 -> #REF! | H11: =#REF! -> #REF! | I11: 0
A12: 0.36 | B12: =FacAnual!G14 -> 947768.54 | C12: Octubre | D12: 0 | F12: 0 | G12: =F12/H12 -> #REF! | H12: =#REF! -> #REF! | I12: 0
A13: 0.48 | B13: =FacAnual!G15 -> 959663.81 | C13: Noviembre | D13: 0 | F13: 0 | G13: =F13/H13 -> #REF! | H13: =#REF! -> #REF! | I13: 0
B14: =FacAnual!G16 -> 1778545.9 | C14: Diciembre | D14: 0 | F14: =B14*0.0829 -> 147441.45 | G14: =F14/H14 -> #REF! | H14: =#REF! -> #REF! | I14: 0
C15: Total anticipado | D15: =SUM(D3:D14) -> 18540 | F15: IRAE C/deduc | G15: IRAE C/d u$s | I15: Aporte patronal
C16: Saldo ant IRAE | D16: =(F16-D15) -> 147441.45 | E16: Total Irae con ded | F16: =SUM(F3:F15) -> 165981.45 | G16: =SUM(G3:G15) -> #REF! | I16: =SUM(I3:I15) -> 0
E18: Total deducciones | F18: =I16 -> 0
E19: Facturado | F19: =A3 -> 0
E20: 0.36 | F20: =F19*0.36 -> 0
E21: 0.48 | F21: =F19*0.48 -> 0
E22: Anticipo | F22: =D15 -> 18540
E23: IRAE al 48 | F23: =(F21-F18)*0.25 -> 0
E24: IRAE al 36 | F24: =(F20-F18)*0.25 -> 0
E25: Saldo a pagar al 48 | F25: =(F23-F22)*0 -> 0
E26: Saldo a pagar al 36 | F26: =(F24-F22)*0 -> 0
A28: Imponible $ 2025 | B28: Facturacion $ | C28: Anticipos Irae | D28: $ | F28: IRAE S/deduc | G28: IRAE C/d u$s | H28: T/C | I28: Aporte patronal
A29: =Facturacion!J216 -> 10039518 | B29: =FacAnual!G85 -> 1568778.6 | C29: Enero | F29: 0 | G29: =F29/H29 -> 0 | H29: 39.9 | I29: 0
B30: =FacAnual!G86 -> 725819.21 | C30: Febrero | F30: 0 | G30: =F30/H30 -> 0 | H30: 39.9 | I30: 0
B31: =FacAnual!G87 -> 663936.49 | C31: Marzo | F31: 0 | G31: =F31/H31 -> 0 | H31: 39.9 | I31: 0
B32: =FacAnual!G88 -> 812738.99 | C32: Abril | D32: 0 | F32: 0 | G32: =F32/H32 -> 0 | H32: 39.9 | I32: 0
B33: =FacAnual!G89 -> 1419839.1 | C33: Mayo | D33: 0 | F33: 0 | G33: =F33/H33 -> 0 | H33: 39.9 | I33: 0
B34: =FacAnual!G90 -> 881912.53 | C34: Junio | D34: 0 | F34: 0 | G34: =F34/H34 -> 0 | H34: 39.9 | I34: 0
B35: =FacAnual!G91 -> 1119541 | C35: Julio | D35: 0 | F35: 0 | G35: =F35/H35 -> 0 | H35: 39.9 | I35: 0
A36: coef irae | B36: =FacAnual!G92 -> 1047323.6 | C36: Agosto | D36: 8110 | F36: 8110 | G36: =F36/H36 -> 203.25815 | H36: 39.9 | I36: 0
A37: 0.12 | B37: =FacAnual!G93 -> 1765931.3 | C37: Setiembre | D37: 8110 | F37: 8110 | G37: =F37/H37 -> 203.25815 | H37: 39.9 | I37: 0
A38: 0.36 | C38: Octubre | D38: 0 | F38: 8110 | G38: =F38/H38 -> 203.25815 | H38: 39.9 | I38: 0
A39: 0.48 | C39: Noviembre | D39: 0 | F39: 8110 | G39: =F39/H39 -> 203.25815 | H39: 39.9 | I39: 0
C40: Diciembre | D40: 0 | F40: 8110 | G40: =F40/H40 -> 203.25815 | H40: 39.9 | I40: 0
C41: Total anticipado | D41: =SUM(D29:D40) -> 16220 | F41: IRAE C/deduc | G41: IRAE C/d u$s | I41: Aporte patronal
C42: Saldo ant IRAE | D42: =(F42-D41) -> 24330 | E42: Total Irae con ded | F42: =SUM(F29:F41) -> 40550 | G42: =SUM(G29:G41) -> 1016.2907 | I42: =SUM(I29:I41) -> 0
E44: Total deducciones | F44: =I42 -> 0
...

Sheet Gastos
A1: Año | B1: Fecha Pago | C1: Centro de Costo | D1: Tipo de Gasto | E1: Proveedor | F1: Concepto | G1: Total COP $ | H1: Total U$S | I1: Neto U$S | J1: Total $ | K1: Neto $ | L1: IVA $ | M1: T/C
A2: 2022 | B2: 44769 | C2: Colombia | D2: Hardware | E2: Tecnoplaza | F2: Notebooks | H2: 2450 | I2: 2450
A3: 2022 | B3: 44774 | C3: Colombia | D3: transferencias | E3: Itau | F3: transferencia | H3: 40 | I3: 40
A4: 2022 | B4: 44774 | C4: Uruguay | D4: Honorarios Profesionales | E4: Gonzalo Cameto | F4: Honorarios profesionales | H4: 4026 | I4: 4026
A5: 2022 | B5: 44774 | C5: Uruguay | D5: Honorarios Profesionales | E5: Fernando Medina | F5: Honorarios profesionales | H5: 3294 | I5: 3294
A6: 2022 | B6: 44774 | C6: Colombia | D6: Honorarios Profesionales | E6: Camilo Arboleda | F6: Honorarios profesionales | H6: 843 | I6: 843
A7: 2022 | B7: 44774 | C7: Uruguay | D7: Sueldos | E7: Santander | F7: trasferencia | H7: 4.68 | I7: 4.68 | J7: 36.33 | K7: 36.33 | U7: DETALLE SERVICIOS REGISTRADOS
A8: 2022 | B8: 44774 | C8: Uruguay | D8: Sueldos | E8: Juan Pellegrini | F8: sueldo | J8: 48518 | K8: 48518 | R8: Hardware | S8: Servicio | T8: Locales | U8: Web | V8: Honorarios Profesionales | W8: Viajes | X8: Varios | Y8: Impuestos | Z8: Sueldos
A9: 2022 | B9: 44774 | C9: Uruguay | D9: Honorarios Profesionales | E9: Rodolfo Vazquez | F9: utilidad mensual | J9: 192212 | K9: 192212 | R9: Notebooks | S9: Codesal | T9: Alquiler | U9: Microsoft | V9: Honorarios | W9: Pasaje aereo | X9: Almuerzo | Y9: BPS | Z9: Andrea Correa
A10: 2022 | B10: 44783 | C10: Colombia | D10: Hardware | E10: S&M COMPUTER SAS | F10: Auriculares | G10: 383700 | H10: 90 | I10: 90 | R10: Monitores | S10: UTE | T10: Gastos Comunes | U10: Google Suite Botmeli | V10: Santiago Lamanna | W10: Hospedaje | X10: Autoland (ACF SA) | Y10: DGI | Z10: Jacqueline Valverde
A11: 2022 | B11: 44788 | C11: Uruguay | D11: Varios | E11: Itau | F11: Gastos Adm Bancos | J11: 1232 | R11: Auriculares | S11: Antel | T11: Impuestos Municipales | U11: Amazon Web Services | V11: Eugenia Lopez | W11: Taxis | X11: coorporacion vial | Y11: BSE
A12: 2022 | B12: 44791 | C12: Uruguay | D12: Impuestos | E12: BPS | F12: bps | J12: 50616 | K12: 1232 | S12: Codesal | U12: Mongobd inc | V12: Ingesol | W12: Comidas | X12: Gastos Adm Bancos
A13: 2022 | B13: 44791 | C13: Uruguay | D13: Varios | E13: Santander | F13: trasferencia | H13: 1.9 | I13: 1.9 | K13: 50616 | S13: Computrabajo | U13: Github inc | V13: Fernando Medina | W13: Varios | X13: Papeleria
A14: 2022 | B14: 44792 | C14: Uruguay | D14: Impuestos | E14: DGI | F14: IVA | J14: 98006 | K14: 98006 | O14: Iva ventas | S14: Buscojobs | U14: Google Cloud | V14: Gonzalo Cameto | W14: Universal Assistence
A15: 2022 | B15: 44792 | C15: Uruguay | D15: Varios | E15: Santander | F15: trasferencia | H15: 1.9 | I15: 1.9 | S15: Forteza | U15: Miro | V15: Camilo Arboleda
A16: 2022 | B16: 44804 | C16: Uruguay | D16: Honorarios Profesionales | E16: Fernando Medina | F16: Honorarios profesionales | H16: 3294 | I16: 2700 | L16: =594*M16 -> 24220.35 | M16: 40.775 | O16: =SUM(Facturacion!I29:I31) -> 169449.55 | S16: CoWork | U16: Zoom | V16: Jose Martinez
A17: 2022 | B17: 44804 | C17: Uruguay | D17: Honorarios Profesionales | E17: Gonzalo Cameto | F17: Honorarios profesionales | H17: 4026 | I17: 3300 | L17: =726*M17 -> 29602.65 | M17: 40.775 | O17: Iva compras | P17: Iva a pagar | U17: Mail track | V17: Miguel Angel Lasso
A18: 2022 | B18: 44804 | C18: Uruguay | D18: Servicio | E18: Codesal | F18: honorarios | J18: 6100 | K18: 5000 | L18: 1100 | O18: =SUM(L2:L19) -> 54923 | P18: =O16-O18 -> 114526.55 | V18: Utilidades socios
A19: 2022 | B19: 44804 | C19: Uruguay | D19: Varios | E19: Santander | F19: comision | J19: 743.11 | K19: 743.11 | V19: Dasuly Giraldo
A20: 2022 | B20: 44805 | C20: Colombia | D20: Honorarios Profesionales | E20: Camilo Arboleda | F20: Honorarios profesionales | H20: 713 | I20: 713
A21: 2022 | B21: 44805 | C21: Colombia | D21: Honorarios Profesionales | E21: David Pernett | F21: Honorarios profesionales | H21: 514 | I21: 514
A22: 2022 | B22: 44805 | C22: Colombia | D22: Honorarios Profesionales | E22: Jose Martinez | F22: Honorarios profesionales | H22: 514 | I22: 514
A23: 2022 | B23: 44805 | C23: Colombia | D23: Honorarios Profesionales | E23: Claudia Garcia Arboleda | F23: Honorarios profesionales | H23: 60 | I23: 60
A24: 2022 | B24: 44805 | C24: Uruguay | D24: Sueldos | E24: Santander | F24: transferencia | J24: 82.57 | K24: 82.57
A25: 2022 | B25: 44805 | C25: Uruguay | D25: Sueldos | E25: Juan Pellegrini | F25: sueldo | J25: 48518 | K25: 48518
A26: 2022 | B26: 44805 | C26: Uruguay | D26: Honorarios Profesionales | E26: Rodolfo Vazquez | F26: utilidad mensual | J26: 192212 | K26: 192212
A27: 2022 | B27: 44805 | C27: Uruguay | D27: Sueldos | E27: Santander | F27: transferencia | H27: 0.87 | I27: 0.87 | J27: 36.09 | K27: 36.09
A28: 2022 | B28: 44805 | C28: Colombia | D28: transferencias | E28: Itau | F28: transferencia | H28: 240 | I28: 240
A29: 2022 | B29: 44811 | C29: Uruguay | D29: Varios | E29: Santander | F29: transferencia | H29: 1.9 | I29: 1.9
A30: 2022 | B30: 44813 | C30: Uruguay | D30: Impuestos | E30: BPS | F30: bps | J30: 58402 | K30: 58402
A31: 2022 | B31: 44813 | C31: Uruguay | D31: Impuestos | E31: BPS | F31: bps irpf | J31: 2767 | K31: 2767
A32: 2022 | B32: 44819 | C32: Uruguay | D32: Varios | E32: Itau | F32: Gastos Adm Bancos | J32: 1232 | K32: 1232
A33: 2022 | B33: 44821 | C33: Uruguay | D33: Impuestos | E33: BSE | F33: accidentes de trabajo | J33: 793 | K33: =J33-L33 -> 650.05 | L33: 142.95 | O33: Iva ventas
A34: 2022 | B34: 44834 | C34: Colombia | D34: Avisos | E34: Computrabajo | F34: avisos | H34: 272 | I34: 272 | O34: =SUM(Facturacion!I32:I35) -> 152225.22
A35: 2022 | B35: 44834 | C35: Uruguay | D35: Honorarios Profesionales | E35: Fernando Medina | F35: Honorarios profesionales | H35: 3294 | I35: 2700 | L35: =594*M35 -> 24704.46 | M35: 41.59 | O35: Iva compras | P35: Iva a pagar
A36: 2022 | B36: 44834 | C36: Uruguay | D36: Honorarios Profesionales | E36: Gonzalo Cameto | F36: Honorarios profesionales | H36: 4636 | I36: 3300 | L36: =836*M36 -> 34769.24 | M36: 41.59 | O36: =SUM(L20:L39) -> 60716.65 | P36: =O34-O36 -> 91508.573
A37: 2022 | B37: 44834 | C37: Uruguay | D37: Servicio | E37: Codesal | F37: honorarios | J37: 6100 | K37: 5000 | L37: 1100
A38: 2022 | B38: 44834 | C38: Uruguay | D38: Varios | E38: Santander | F38: comision | J38: 749.17 | K38: 749.17
A39: 2022 | B39: 44834 | C39: Uruguay | D39: Varios | E39: Santander | F39: transferencia | H39: 1.9 | J39: 83.24 | K39: 83.24
A40: 2022 | B40: 44837 | C40: Uruguay | D40: Varios | E40: Santander | F40: transferencia | H40: 2.77 | I40: 2.77 | J40: 36.31 | K40: 36.31
...

Sheet CtaCteMN
E1: SANTANDER | N1: ITAU
D2: Saldo inicial | E2: 0 | F2: Saldo Actual | G2: =SUM(B4:B815)-SUM(C4:C815) -> 169960.1 | O2: Saldo Actual | P2: =SUM(M4:M453)-SUM(N4:N453) -> 0
A3: Mes | B3: Crédito | C3: Débito | D3: Concepto | E3: Nota | H3: Disponible | I3: =G2-I2 -> 169960.1 | L3: Fecha | M3: Crédito | N3: Débito | O3: Concepto | Q3: Disponible | R3: =P2-R2 -> 0
A4: 27/01/2022 | B4: 250000 | D4: compra pesos | L4: 15/08/2022 | M4: 1232 | O4: venta dolares entre cta
A5: 44563 | C5: 138307 | D5: Honorarios Cameto | L5: 15/08/2022 | N5: 1232 | O5: costo banking card
A6: 44563 | C6: 109800 | D6: Honorarios Medina | L6: 15/09/2022 | M6: 1232 | O6: venta dolares entre cta
A7: 44563 | C7: 84.61 | D7: costo transferencia | L7: 15/09/2022 | N7: 1232 | O7: costo banking card
A8: 24/02/2022 | B8: 250000 | D8: compra pesos | L8: 14/10/2022 | M8: 1232 | O8: venta dolares entre cta
A9: 44595 | C9: 138307 | D9: Honorarios Cameto | L9: 14/10/2022 | N9: 1232 | O9: costo banking card
A10: 44595 | C10: 109800 | D10: honorarios Medina | L10: 15/11/2022 | M10: 1232 | O10: venta dolares entre cta
A11: 44595 | C11: 82.14 | D11: costo transferencia | L11: 15/11/2022 | N11: 1232 | O11: costo banking card
A12: 44837 | B12: 189075.6 | D12: pago mevir | E12: Fac A003 | L12: 15/12/2022 | M12: 1232 | O12: venta dolares entre cta
A13: 14/03/2022 | C13: 7595 | D13: BPS | L13: 15/12/2022 | N13: 1232 | O13: costo banking card
A14: 24/03/2022 | B14: 184242.2 | D14: pago mevir | E14: Fac 008 | L14: 13/01/2023 | M14: 1232 | O14: venta dolares entre cta
A15: 44565 | C15: 109800 | D15: honorarios Medina | L15: 13/01/2023 | N15: 1232 | O15: costo banking card
A16: 44565 | C16: 79.19 | D16: costo transferencia | L16: 15/02/2023 | M16: 1232 | O16: venta dolares entre cta
A17: 44565 | C17: 3500 | D17: Pago Escribana | L17: 15/02/2023 | N17: 1232 | O17: costo banking card
A18: 44685 | C18: 12200 | D18: pago contador | E18: Febrero y marzo | L18: 15/03/2023 | M18: 1232 | O18: venta dolares entre cta
A19: 20/04/2022 | C19: 6881 | D19: BPS | L19: 15/03/2023 | N19: 1232 | O19: costo banking card
A20: 26/04/2022 | B20: 270000 | D20: compra pesos | L20: 14/04/2023 | M20: 1232 | O20: venta dolares entre cta
A21: 27/04/2022 | B21: 200000 | D21: compra pesos | L21: 14/04/2023 | N21: 1232 | O21: costo banking card
A22: 29/04/2022 | C22: 1128.94 | D22: comision por producto | L22: 26/04/2023 | M22: 2452.1 | O22: devolucion ML por compra
A23: 29/04/2022 | B23: 26000 | D23: compra pesos | L23: 45143 | M23: 8800 | O23: pesos de santander para pago tarjeta visa
A24: 44597 | C24: 109800 | D24: honorarios Medina | L24: 45143 | N24: 11048.55 | O24: pago tarjeta visa pesos
A25: 44597 | C25: 78.64 | D25: costo transferencia | L25: 15/05/2023 | M25: 1028.45 | O25: venta dolares entre cta
A26: 44597 | C26: 192212 | D26: utilidades Javier | L26: 15/05/2023 | N26: 1232 | O26: costo banking card
A27: 44597 | C27: 78,60 | D27: costo transferencia | L27: 15/06/2023 | M27: 1232 | O27: venta dolares entre cta
A28: 44597 | C28: 192212 | D28: utilidades Rodolfo | L28: 15/06/2023 | N28: 1232 | O28: costo banking card
A29: 44597 | C29: 237000 | D29: prestamo socios | L29: 45023 | M29: 2600 | O29: transferencia de cta santander pesos
A30: 44900 | B30: 13000 | D30: compra pesos | L30: 45206 | N30: 1005.39 | O30: pago tarjeta visa pesos
A31: 44900 | C31: 6881 | D31: BPS | L31: 14/07/2023 | N31: 1232 | O31: costo banking card
A32: 44900 | C32: 6100 | D32: pago contador | L32: 44934 | M32: 111600 | O32: transferencia recibida santander para pagos sueldos y mas
A33: 19/05/2022 | B33: 171497.72 | D33: pago mevir | E33: Fac A013 | L33: 44934 | N33: 105000 | O33: Sueldo Fernanda Castro
A34: 19/05/2022 | C34: 846 | D34: adelanto socio | L34: 45115 | N34: 6496.36 | O34: pago tarjeta visa pesos
A35: 30/05/2022 | C35: 2800 | D35: adelanto socio | L35: 15/08/2023 | M35: 797.75 | O35: venta dolares entre cta
A36: 31/05/2022 | B36: 160000 | D36: compra pesos | L36: 15/08/2023 | N36: 1264 | O36: costo banking card
A37: 44567 | C37: 188566 | D37: utilidad Rodolfo | L37: 15/09/2023 | M37: 1264 | O37: venta dolares entre cta
A38: 44567 | C38: 109800 | D38: honorarios medina | L38: 15/09/2023 | N38: 1264 | O38: costo banking card
A39: 44567 | C39: 36.03 | D39: costo transferencia | L39: 13/10/2023 | M39: 1264 | O39: venta dolares entre cta
A40: 44718 | C40: 6100 | D40: pago contador | L40: 13/10/2023 | N40: 1264 | O40: costo banking card
...

Sheet CtaCteUSS
C1: SANTANDER | J1: ITAU | Q1: MERCURY | X1: PAYONEER
C3: Saldo Actual | D3: =SUM(B7:B589)-SUM(C7:C589) -> 9236.38 | J3: Saldo Actual | K3: =SUM(J7:J619)-SUM(K7:K619) -> 29377.6 | Q3: Saldo Actual | R3: =SUM(Q7:Q579)-SUM(R7:R579) -> -16753.33 | X3: Saldo Actual | Y3: =SUM(X7:X579)-SUM(Y7:Y579) -> 41.96
D4: Disponible | E4: =D3-F3 -> 9236.38 | K4: Disponible | L4: =K3-M3 -> 29377.6 | R4: Disponible | S4: =R3-T3 -> -16753.33 | Y4: Disponible | Z4: =Y3-AA3 -> 41.96
A6: Fecha | B6: Crédito | C6: Débito | D6: Concepto | I6: Fecha | J6: Crédito | K6: Débito | L6: Concepto | P6: Fecha | Q6: Crédito | R6: Débito | S6: Concepto | W6: Fecha | X6: Crédito | Y6: Débito | Z6: Concepto
A7: 27/01/2022 | B7: 10000 | D7: Pago UXDivers | E7: Fac A002 | I7: 44569 | J7: 5000 | L7: deposito cta santander | P7: 45693 | Q7: 0 | W7: 45388 | X7: 1300 | Z7: transferencia de itau U$S
A8: 28/01/2022 | B8: 5433 | D8: Pago UXDivers | E8: Fac A002 | I8: 44569 | K8: 843 | L8: honorarios Camilo Arboleda | P8: 45782 | R8: 3100 | S8: envio a payoneer | W8: 45388 | Y8: 20 | Z8: comision banco x transferencia
A9: 31/01/2022 | C9: 5660 | D9: venta dolares | I9: 44569 | K9: 40 | L9: costo transferencia | P9: 45782 | R9: 15 | S9: comision Camilo Arboleda | W9: 45388 | Y9: 12.8 | Z9: comision payoneer
A10: 31/01/2022 | C10: 1.9 | D10: costo transferencia | I10: 15/08/2022 | K10: 31.63 | L10: traspaso a cta pesos | P10: 45782 | R10: 1300 | S10: Honorarios Camilo Arboleda | W10: 45418 | Y10: 300 | Z10: Honorarios Amelia Barcia
A11: 31/01/2022 | B11: 4200 | D11: pago UXDivers | E11: Fac A001 | I11: 44570 | K11: 713 | L11: honorarios Camilo Arboleda | P11: 45782 | R11: 833.33 | S11: Honorarios Luciano Putruele | W11: 45418 | Y11: 800 | Z11: Honorarios Amelia Barcia
A12: 44594 | C12: 1290 | D12: devolucion compra mac a javier | I12: 44570 | K12: 60 | L12: costo transferencia | P12: 45813 | R12: 40 | S12: Cursor | W12: 21/06/2024 | Y12: 95 | Z12: pago personal de Rodolfo | AA12: descontado de las devoluciones en dolares
A13: 44594 | C13: 1.9 | D13: costo transferencia | I13: 44570 | K13: 514 | L13: Honorarios Jose Manuel Martinez | P13: 45813 | R13: 40 | S13: Cursor | W13: 26/06/2024 | X13: 1300 | Z13: transferencia de itau U$S
A14: 21/02/2022 | B14: 3250 | D14: pago UXDivers | E14: Fac A004 | I14: 44570 | K14: 60 | L14: costo transferencia | P14: 45813 | R14: 2500 | S14: Marcela Papeleo | T14: Argentina - RRHH | W14: 26/06/2024 | Y14: 20 | Z14: comision banco x transferencia
A15: 24/02/2022 | C15: 8000 | D15: venta dolares | I15: 44570 | K15: 514 | L15: Honorarios David Pernett | P15: 45843 | R15: 110 | S15: Lazo fintech | W15: 26/06/2024 | Y15: 12.8 | Z15: comision payoneer
A16: 24/02/2022 | C16: 1.9 | D16: costo transferencia | I16: 44570 | K16: 60 | L16: costo transferencia | P16: 45843 | R16: 2500 | S16: Xtrategy | T16: tercer mes de tabajo | W16: 28/06/2024 | Y16: 1100 | Z16: Honorarios Amelia Barcia
A17: 24/02/2022 | C17: 5278 | D17: venta dolares | E17: se PAGO IVA con esta venta y la anterior | I17: 44570 | K17: 60 | L17: Honorarios Claudia garcia | P17: 45694 | R17: 15 | S17: comision Camilo Arboleda | W17: 15/07/2024 | Y17: 100 | Z17: reserva sala cowork | AA17: envio a camilo
A18: 24/02/2022 | C18: 1.9 | D18: costo transferencia | I18: 44570 | K18: 60 | L18: costo transferencia | P18: 45694 | R18: 1300 | S18: Honorarios Camilo Arboleda | W18: 29/07/2024 | Y18: 50 | Z18: prueba honorarios miguel lasso
A19: 25/02/2022 | B19: 10000 | D19: pago UXDivers | E19: Fac A005 | I19: 44813 | J19: 4171 | L19: pago UXdivers | M19: Fac A027 | P19: 45694 | R19: 2500 | S19: Honorarios Luciano Putruele | W19: 29/07/2024 | Y19: 50 | Z19: prueba honorarios david
A20: 44623 | B20: 626 | D20: pago UXDivers | E20: Fac A005 | I20: 44813 | J20: 9200 | L20: pago UXdivers | M20: Fac A024 | P20: 45936 | R20: 2500 | S20: Xtrategy | T20: cuarto mes de tabajo | W20: 31/07/2024 | X20: 2040 | Z20: transferencia de itau U$S
A21: 21/03/2022 | B21: 3800 | D21: pago UXDivers | E21: Fac A009 | I21: 15/09/2022 | K21: 31.11 | L21: traspaso a cta pesos | W21: 31/07/2024 | Y21: 20.4 | Z21: comision banco x transferencia
A22: 22/03/2022 | C22: 4953 | D22: venta dolares | E22: se pago el IVA con esta venta de dolares | I22: 30/09/2022 | J22: 11216.18 | L22: pago UXdivers | M22: Fac A028 | W22: 45299 | Y22: 900 | Z22: honorarios Miguel Lasso
A23: 22/03/2022 | C23: 1.9 | D23: costo transferencia | I23: 44661 | K23: 700 | L23: honorarios Camilo Arboleda | W23: 45299 | Y23: 1100 | Z23: Honorarios Amelia Barcia
A24: 28/03/2022 | B24: 7788 | D24: pago UXDivers | E24: Fac A010 | I24: 44661 | K24: 40 | L24: costo transferencia | W24: 45299 | Y24: 50 | Z24: prueba honorarios Jose
A25: 29/03/2022 | B25: 5000 | D25: pago UXDivers | E25: Fac A010 | I25: 44661 | K25: 510 | L25: honorarios david Pernett | W25: 29/08/2024 | X25: 4720 | Z25: transferencia de itau U$S
A26: 44565 | C26: 4514 | D26: honorarios Cameto | I26: 44661 | K26: 40 | L26: costo transferencia | W26: 29/08/2024 | Y26: 47.2 | Z26: comision banco x transferencia
A27: 44655 | B27: 9000 | D27: pago Ingesol | E27: Fac A007 | I27: 44661 | K27: 510 | L27: honorarios jose Manuel Martinez | W27: 45331 | Y27: 1300 | Z27: honorarios Jose Manuel Martinez
A28: 44655 | C28: 2500 | D28: compra mac maquina rodo | I28: 44661 | K28: 40 | L28: costo transferencia | W28: 45331 | Y28: 1300 | Z28: honorarios David Pernett
A29: 44685 | B29: 8019 | D29: pago Ingesol | E29: Fac A007 | I29: 44752 | J29: 3925 | L29: pago UXdivers | M29: Fac A030 | W29: 45331 | Y29: 900 | Z29: honorarios miguel Lasso
A30: 27/04/2022 | C30: 9000 | D30: venta dolares | I30: 14/10/2022 | K30: 25 | L30: comision por transferencia | M30: Orga+ | W30: 45331 | Y30: 1100 | Z30: Honorarios Amelia Barcia
A31: 27/04/2022 | C31: 1.9 | D31: costo transferencia | I31: 14/10/2022 | J31: 7450 | L31: pago Orga+ | M31: Fac Exportacion A001 | W31: 27/09/2024 | X31: 4650 | Z31: transferencia de itau U$S
A32: 29/04/2022 | C32: 3175 | D32: venta dolares | I32: 14/10/2022 | K32: 30.76 | L32: traspaso a cta pesos | W32: 27/09/2024 | Y32: 46.5 | Z32: comision banco x transferencia
A33: 29/04/2022 | C33: 1.9 | D33: costo transferencia | I33: 20/10/2022 | J33: 7912 | L33: pago UXdivers | M33: Fac A031 | W33: 45301 | Y33: 1300 | Z33: honorarios Jose Manuel Martinez
A34: 44597 | B34: 10000 | D34: pago UXDivers | E34: Fac A012 | I34: 44572 | K34: 482 | L34: honorarios david Pernett | W34: 45301 | Y34: 1300 | Z34: honorarios David Pernett
A35: 44597 | B35: 6353 | D35: pago UXDivers | E35: Fac A012 | I35: 44572 | K35: 40 | L35: costo transferencia | W35: 45301 | Y35: 900 | Z35: honorarios miguel Lasso
A36: 44597 | C36: 4026 | D36: honorarios Cameto | I36: 44572 | K36: 482 | L36: honorarios jose Manuel Martinez | W36: 45301 | Y36: 404 | Z36: Honorarios Amelia Barcia
A37: 44625 | B37: 4350 | D37: pago UXDivers | E37: Fac 011 | I37: 44572 | K37: 40 | L37: costo transferencia | W37: 29/10/2024 | X37: 4650 | Z37: transferencia de itau U$S
A38: 44900 | C38: 313 | D38: venta dolares | I38: 44572 | K38: 700 | L38: honorarios camilo Arboleda | W38: 29/10/2024 | Y38: 46.5 | Z38: comision banco x transferencia
A39: 44900 | C39: 1.9 | D39: costo transferencia | I39: 44572 | K39: 40 | L39: costo transferencia | W39: 45302 | Y39: 1300 | Z39: honorarios Jose Manuel Martinez
A40: 19/05/2022 | B40: 3200 | D40: pago UXDivers | E40: Fac A014 | I40: 44753 | K40: 24.88 | L40: debito VISA credito | W40: 45302 | Y40: 1300 | Z40: honorarios David Pernett
A41: 23/05/2022 | B41: 6624 | D41: pago UXDivers | E41: Fac A015 | I41: 44784 | J41: 3450 | L41: pago UXdivers | M41: Fac A033 | W41: 45302 | Y41: 900 | Z41: honorarios miguel Lasso
A42: 44567 | C42: 4026 | D42: honorarios Cameto | I42: 15/11/2022 | K42: 31.91 | L42: traspaso a cta pesos | W42: 45302 | Y42: 1100 | Z42: Honorarios Amelia Barcia
...

Sheet CertificadosFinal
C2: Facturas | H2: Certificados
B3: Mes | C3: Monto IVA Fac | D3: Cliente | E3: Saldo Pendiente | F3: Total Cert. | G3: Nº Certificado | H3: Fecha transaccion | I3: Nº Boleto | J3: intervencion | K3: Emitido | L3: Uso mes | M3: IVA | N3: IRNR | O3: IP | P3: BPS
B4: 44562 | C4: 192099.09 | D4: UXDivers | E4: =C4-F4 -> 55101.09 | F4: 136998 | G4: 291253 | H4: 25/04/2022 | I4: 8255501 | J4: 62904616410 | K4: S
D5: UXDivers | E5: =E4-F5 -> 7217.09 | F5: 47884 | G5: 313608 | H5: 18/05/2022 | I5: 8428724 | J5: 62904716520 | K5: S
B6: 44562 | C6: 134823.38 | D6: UXDivers | E6: =E5+C6-F6 -> 24953.47 | F6: 117087 | G6: 344151 | H6: 18/06/2022 | I6: 8685387 | J6: 62904853730 | K6: S
D7: UXDivers | E7: =E6-F7 -> 0.47 | F7: 24953 | G7: 344152 | H7: 22/07/2022 | I7: 8943599 | J7: 62904853730 | K7: S
B8: 44593 | C8: 157013.71 | D8: UXDivers | E8: =E7+C8-F8 -> 0.18 | F8: 157014 | G8: 3905941 | H8: 22/07/2022 | I8: 8943599 | J8: 96203017850 | K8: S
B9: 44621 | C9: 186599.86 | D9: UXDivers | E9: =E8+C9-F9 -> 88594.04 | F9: 98006 | G9: 397881 | H9: 19/08/2022 | I9: 9123366 | J9: 62905093910 | K9: S
D10: UXDivers | E10: =E9+C10-F10 -> 1.04 | F10: 88593 | G10: 397882 | H10: 44813 | I10: 9248746 | J10: 62905093910 | K10: S
B11: 44652 | C11: 88238.58 | D11: UXDivers | E11: =E10+C11-F11 -> 53453.62 | F11: 34786 | G11: 413083 | H11: 44813 | I11: 9248746 | J11: 62905161700 | K11: S
D12: UXDivers | E12: =(E11+C12)-F12 -> 1.62 | F12: 53452 | G12: 413084 | H12: 21/10/2022 | I12: 9520500 | J12: 62905161700 | K12: S
B13: 44682 | C13: 136356.06 | D13: UXDivers | E13: =(E12+C13)-F13 -> 89716.68 | F13: 46641 | G13: 447180 | H13: 21/10/2022 | I13: 9520500 | J13: 62905315780 | K13: S
D14: UXDivers | E14: =(E13+C14)-F14 -> 1.68 | F14: 89715 | G14: 447181 | H14: 23/11/2022 | I14: 9737275 | J14: 62905315780 | K14: S
B15: 44713 | C15: 137776.87 | D15: UXDivers | E15: =(E14+C15)-F15 -> 137070.55 | F15: 708 | G15: 474095 | H15: 23/11/2022 | I15: 9737275 | J15: 62905437900 | K15: S
D16: UXDivers | E16: =(E15+C16)-F16 -> 39639.55 | F16: 97431 | G16: 489362 | H16: 18/12/2022 | I16: 9854492 | J16: 62905506400 | K16: S
D17: UXDivers | E17: =(E16+C17)-F17 -> 1.55 | F17: 39638 | G17: 489363 | H17: 16/02/2023 | I17: 10205516 | J17: 62905506400 | K17: S
B18: 44743 | C18: 116719.02 | D18: UXDivers | E18: =(E17+C18)-F18 -> 1.57 | F18: 116719 | G18: 3983783 | H18: 16/02/2023 | I18: 10205516 | J18: 96203460260 | K18: S
B19: 44774 | C19: 137962.99 | D19: UXDivers | E19: =(E18+C19)-F19 -> -66.44 | F19: 138031 | G19: 3989493 | H19: 16/02/2023 | I19: 10205516 | J19: 96203489430 | K19: S
B20: 44805 | C20: 108306.18 | D20: UXDivers | E20: =(E19+C20)-F20 -> 68935.74 | F20: 39304 | G20: 534179 | H20: 16/02/2023 | I20: 10205516 | J20: 62905709150 | K20: S
D21: UXDivers | F21: 69002 | G21: 534180 | H21: 16/02/2023 | I21: 10205532 | J21: 62905709150 | K21: S | L21: Enero | M21: 55853 | N21: 13149
B22: 44835 | C22: 98020.79 | D22: UXDivers | E22: =(E21+C22)-F22 -> 32989.79 | F22: 65031 | G22: 557367 | H22: 17/03/2023 | I22: 10385956 | J22: 62905814100 | K22: S | L22: Febrero | M22: 49911 | N22: 15120
B23: 44866 | D23: UXDivers | E23: =(E22+C23)-F23 -> 17348.79 | F23: 15641 | G23: 557368 | H23: 24/05/2023 | I23: 10921807 | J23: 62905814100 | K23: S | L23: Marzo | M23: -20889 | N23: 15641
E24: =(E23+C24)-F24 -> 1804.79 | F24: 15544 | G24: 557368 | H24: 24/05/2023 | I24: 10921807 | J24: 62906121330 | K24: S
B25: 44866 | C25: 104120.83 | D25: UXDivers | E25: =(E24+C25)-F25 -> 58594.62 | F25: 47331 | G25: 624330 | H25: 24/05/2023 | I25: 10921807 | J25: 62906121330 | K25: S | L25: Abril | M25: 68220 | N25: 15544
B26: 44896 | C26: 100787.4 | D26: UXDivers | E26: =(E25+C26)-F26 -> 146759.02 | F26: 12623 | G26: 654436 | H26: 22/06/2023 | I26: 11157051 | K26: S | L26: Diciembre 2022 | O26: 12623
B27: 44927 | C27: 38363.49 | D27: UXDivers | E27: =(E26+C27)-F27 -> 139151.51 | F27: 45971 | G27: 654435 | H27: 22/06/2023 | I27: 11157205 | K27: S | L27: Mayo | M27: 30384 | N27: 16506 | O27: =1389*3 -> 4167
B28: 44958 | C28: =Facturacion!I55 -> 10305.768 | D28: UXDivers | E28: =(E27+C28)-F28 -> 144371.28 | F28: 5086 | G28: 654439 | H28: 22/06/2023 | I28: 11157205 | K28: S | L28: Mayo
B29: 44986 | C29: =Facturacion!I58 -> 30330.135 | D29: UXDivers | E29: =(E28+C29)-F29 -> 155646.41 | F29: 19055 | G29: 681613 | H29: 23/07/2023 | I29: 11373870 | K29: S | L29: Junio | M29: 0 | N29: 17666 | O29: 1389
B30: 45017 | C30: =Facturacion!I61 -> 30502.829 | D30: UXDivers | E30: =(E29+C30)-F30 -> 183382.24 | F30: 2767 | G30: 686821 | H30: 26/07/2023 | I30: 11415190 | K30: S | L30: irpf julio 2022 | M30: 2767
B31: 45047 | C31: =Facturacion!I64 -> 31959.675 | D31: UXDivers | E31: =(E30-F31) -> 164188.24 | F31: 19194 | G31: 697640 | H31: 45177 | I31: 11500619 | K31: S | L31: Julio | N31: 19194
B32: 45078 | C32: 0 | D32: UXDivers | E32: =(E31-F32) -> 142216.24 | F32: 21972 | G32: 739771 | H32: 21/09/2023 | I32: 11832875 | K32: S | L32: Agosto | N32: 21972
B33: 45108 | C33: =Facturacion!I65 -> 34231.109 | D33: UXDivers | E33: =(E32-F33)+C31 -> 171397.92 | F33: 2778 | G33: 739787 y 739777 | H33: 21/09/2023 | I33: 11832972 | K33: S | L33: Agosto | O33: =1389*2 -> 2778 | Q33: IP julio y agosto
B34: 45108 | C34: =Facturacion!I67 -> 28172.672 | D34: UXDivers | E34: =(E33-F34)+C33 -> 42629.026 | F34: 163000 | G34: 1395,1412 -1416 | H34: 14/11/2023 | K34: S | L34: Octubre | P34: 163000
B35: 45139 | C35: =Facturacion!I69 -> 33574.662 | D35: UXDivers | E35: =(E34-F35)+C34 -> 68023.698 | F35: 2778 | G35: 797303 | H35: 19/11/2023 | I35: 12275406 | K35: S | L35: Octubre | O35: 2778 | Q35: IP de setiembre y octubre
B36: 45170 | C36: =Facturacion!I72 -> 35201.628 | D36: UXDivers | E36: =(E35-F36)+C35+C36 -> 35201.988 | F36: =5619+62404+33575 -> 101598 | G36: 199119921993 | H36: 13/12/2023 | K36: S | L36: Noviembre | P36: =5619+62404+33575 -> 101598
B37: 45200 | C37: =Facturacion!I74 -> 38673.536 | D37: UXDivers | E37: =E36-F37 -> -0.0115 | F37: 35202 | G37: 3070 | H37: 17/01/2024 | K37: S | L37: Enero 2024 | P37: 35202 | Q37: parte del bps de diciembre
B38: 45231 | C38: =Facturacion!I76 -> 35260.082 | D38: UXDivers | E38: =E37-F38+C37+C38 -> 536.6065 | F38: 73397 | G38: 754392 | H38: 13/03/2024 | K38: S | L38: Febrero | P38: 73397 | Q38: bps de febrero
B39: 45261 | C39: =Facturacion!I80 -> 33051.634 | D39: UXDivers | E39: =E38-F39+C39 -> 536.2405 | F39: 33052 | G39: 4277 | H39: 45569 | K39: S | L39: Marzo | P39: =F39+F40 -> 33589 | Q39: bps de marzo
E40: =E39-F40+C40 -> -0.7595 | F40: 537 | G40: 880420 | H40: 45569
B41: 45444 | C41: =Facturacion!I101 -> 27862.912 | D41: UXDivers | E41: =E40-F41+C41 -> -0.8475 | F41: 27863 | G41: 14446984 | H41: 18/09/2024 | K41: S | L41: Agosto | M41: 27863
...

Sheet Prestamos
A1: PESOS
A2: Prestamos a pagar
B3: Fecha | D3: Concepto | E3: Monto $ | F3: Pagado S/N | H3: A Pagar $ | I3: A Cobrar $
I4: =SUMIF($F13:$F15,"<>S",$E13:$E15) -> 0
A11: Prestamos a cobrar
B12: Fecha | D12: Concepto | E12: Monto $ | F12: Cobrado S/N
B13: 2022 | D13: prestamo socio | E13: 237000 | F13: S
B14: 31/12/2023 | D14: retiro caja | E14: 432000 | F14: S
B15: 45870 | D15: devolucion iva porto | E15: 2662 | F15: S
A16: DOLARES
A17: Prestamos a pagar
B18: Fecha | D18: Concepto | E18: Monto U$S | F18: Pagado S/N | H18: A Pagar U$S | I18: A Cobrar U$S
B19: 44937 | D19: prestamo socio | E19: 15000 | F19: S | H19: =SUMIF($F19:$F25,"<>S",$E19:$E25) -> 13784.02 | I19: =SUMIF($F27:$F73,"<>S",$E27:$E73) -> 0
B20: 31/12/2023 | D20: prestamo socio | E20: 20209 | F20: S
B21: 31/7/2025 | D21: cierre ejercicio - prestamo Rodo | E21: =13189.02+595 -> 13784.02
A26: Prestamos a cobrar
B27: Fecha | D27: Concepto | E27: Monto U$S | F27: Cobrado S/N
B28: 44569 | D28: prestamo socio | E28: 23909 | F28: S
B29: 31/12/2023 | D29: retiro caja | E29: 22875 | F29: S

Sheet APagar
A1: Cuentas a pagar MN
B2: Fecha | C2: Proveedor | D2: Concepto | E2: Monto $ | F2: Pagado | H2: A Pagar $ | I2: A pagar u$s
B3: 44562 | C3: A Signum | D3: adelanto apertura SAS | E3: 34173.6 | F3: S | H3: =SUMIF(F2:F9,"<>S",E2:E9) -> 0 | I3: =SUMIF(F11:F58,"<>S",E11:E58) -> 5750
B4: 20/01/2022 | C4: A Signum | D4: certificado ID Abitab | E4: 3500 | F4: S
B5: 20/01/2022 | C5: A Signum | D5: IVA certificado Abitab | E5: 1300 | F5: S
B6: 20/01/2022 | C6: A Signum | D6: escribano paiva BCU | E6: 4500 | F6: S
B7: 20/01/2022 | C7: A Signum | D7: Forteza | E7: 5008 | F7: S
B8: 44621 | C8: oscar | D8: pago DGI | E8: 283871 | F8: S
A10: Cuentas a pagar u$s
B11: Fecha | C11: Proveedor | D11: Concepto | E11: Monto | F11: Pagado
B12: 27/01/2022 | C12: Oscar | D12: dolares | E12: 5660 | F12: S
B13: 16/02/2022 | C13: Aporte socios | D13: UXDivers dic 2021 | E13: 19633 | F13: S
B14: 44652 | C14: Oscar | D14: dolares | E14: 3175 | F14: S
B15: 44900 | C15: Oscar | D15: dolares | E15: 313 | F15: S
B16: 44567 | C16: Oscar | D16: dolares | E16: 4000 | F16: S
B17: 44774 | C17: Oscar | D17: dolares | E17: 6000 | F17: S
B18: 44866 | C18: Oscar | D18: dolares | E18: 7800 | F18: S
B19: 44896 | C19: Oscar | D19: dolares | E19: 7850 | F19: S
B20: 45413 | C20: iva camioneta | D20: iva camioneta | E20: 7813 | F20: S
B21: 45841 | C21: XTrategy | D21: primer mes de trabajo | E21: 2000 | F21: S
B22: 45661 | C22: XTrategy | D22: Segundo mes de trabajo | E22: 2500 | F22: S
B23: 45843 | C23: XTrategy | D23: tercer mes de trabajo | E23: 2500 | F23: S
B24: 45936 | C24: XTrategy | D24: Cuarto mes de trabajo | E24: 2500 | F24: S
B25: 45662 | C25: Oscar | D25: dolares | E25: 5769 | F25: S
B26: 22/07/2025 | C26: Papaleo | D26: honorarios karina Montero | E26: 3000 | F26: S
B27: 45778 | C27: XTrategy | E27: 2500 | F27: S
B28: 45809 | C28: XTrategy | E28: 2500 | F28: S
B29: 45839 | C29: XTrategy | E29: 2500 | F29: S
B30: 45870 | C30: XTrategy | E30: 2500 | F30: S | G30: Lo marco como pago porque se va a pagar desde mercury
B31: 45901 | C31: XTrategy | E31: 2500 | F31: S | G31: Lo marco como pago porque se va a pagar desde mercury
B32: 45658 | C32: Visa | E32: 1600 | F32: S
B33: 45870 | C33: visa tarjeta | E33: 630 | F33: S
B34: 45901 | C34: gonzalo fleitas | E34: 6810 | F34: S
B35: 45931 | C35: Ignacio Fernandez | E35: =5500/2 -> 2750
B36: 45962 | C36: Papaleo/Bolino | E36: =6000/2 -> 3000
